Workbook

Sheet برنامه ۷۰ روزه
A1: برنامه ۷۰ روزه آمادگی برای آزمون ÖSD Zertifikat B2 (هدف: بالای ۹۵٪)
A2: راهنما: هر روز دو مبحث گرامری دارد و هر مبحث دو مثال با ترجمه. ستون «وضعیت» را (از فهرست کشویی) پر کنید تا برگه پیگیری پیشرفت خودکار به‌روز شود. تاریخ شروع در برگه «پیگیری پیشرفت» (خانه B3) قابل تغییر است. رنگ سبز: فاز ۱، زرد: فاز ۲، نارنجی: فاز ۳، قرمز: روز آزمون آزمایشی.
A4: روز | B4: هفته | C4: فاز | D4: تاریخ | E4: تمرکز اصلی روز | F4: گرامر اول | G4: مثال ۱ از گرامر اول (آلمانی و ترجمه) | H4: مثال ۲ از گرامر اول (آلمانی و ترجمه) | I4: گرامر دوم | J4: مثال ۱ از گرامر دوم (آلمانی و ترجمه) | K4: مثال ۲ از گرامر دوم (آلمانی و ترجمه) | L4: دقیقه گرامر | M4: Lesen (خواندن) | N4: دقیقه | O4: Hören (شنیدن) | P4: دقیقه | Q4: Schreiben (نوشتن) | R4: دقیقه | S4: Sprechen (گفتار) | T4: دقیقه | U4: Wortschatz (واژگان) | V4: دقیقه | W4: مجموع دقایق روز | X4: هدف اندازه‌پذیر روز | Y4: وضعیت انجام
A5: 1 | B5: 1 | C5: فاز ۱: تثبیت پایه | D5: ='پیگیری پیشرفت'!$B$3+A5-1 -> 46303 | E5: خواندن | F5: Präsens: starke und unregelmäßige Verben (زمان حال: افعال قوی و بی‌قاعده) | G5: Der Techniker liest die Messwerte und fährt dann zum Kraftwerk. « تکنسین مقادیر اندازه‌گیری را می‌خواند و سپس به نیروگاه می‌رود. » | H5: Sie spricht fließend Deutsch und hilft ihren Kollegen beim Schreiben der Berichte. « او روان آلمانی صحبت می‌کند و در نوشتن گزارش‌ها به همکارانش کمک می‌کند. » | I5: Perfekt mit haben und sein (ماضی نقلی با haben و sein) | J5: Ich habe gestern den Transformator geprüft. « من دیروز ترانسفورماتور را بررسی کردم. » | K5: Wir sind am Montag nach Wien geflogen und haben dort eine Schulung besucht. « ما دوشنبه به وین پرواز کردیم و آنجا در یک دوره آموزشی شرکت کردیم. » | L5: 40 | M5: صفحه رسمی نمونه‌آزمون گوته B2 ـ Teil 1 «Moderne Lebensformen» (چهار پست انجمن؛ ۱۸ دقیقه): ۹ جمله را به افراد نسبت دهید. پاسخ را همان‌جا بررسی کنید. 🔗 https://bfu.goethe.de/b2_mod_2MX6/lesen.php | N5: 40 | O5: صفحه رسمی گوته B2 ـ Teil 1: پنج گفت‌وگو و جمله کوتاه (ادبیات، پرداخت نقدی، کارآموزی، پلاک دوچرخه، موضوع سمینار)؛ هر متن فقط یک بار؛ ۱۰ تکلیف. 🔗 https://bfu.goethe.de/b2_mod_2MX6/hoeren.php | P5: 20 | Q5: ویدیو: «Wie schreibe ich einen Leserbrief? ـ Aufbau, Gliederung & Inhalt» (Die Merkhilfe): ساختار را یادداشت کنید، سپس متن نظرتان را بنویسید. سپس درباره «Arbeit und Beruf» بنویسید و ساختار گرامری امروز را به‌کار ببرید: Präsens. 🔗 https://www.youtube.com/watch?v=jrZ1A_BLZZA | R5: 20 | S5: ویدیوی رسمی ÖSD: «ÖSD Zertifikat B2 – Mündliche Prüfung (Sprechen)»: ساختار واقعی را ببینید، بعد یک تکلیف مشابه را ضبط کنید. سپس خودتان درباره «Migration und Integration» صحبت کنید و ضبط کنید؛ ساختار گرامری امروز: Perfekt mit haben und sein. 🔗 https://www.youtube.com/watch?v=nFQljN4Oeio | T5: 15 | U5: متن مقاله ویکی‌پدیای آلمانی «Hochschule»: ۱۵ واژه یا ترکیب دشوار را از آن بیرون بکشید، ‌معنی و حرف تعریف را بنویسید و هر کدام را در یک جمله خودتان به‌کار ببرید. 🔗 https://de.wikipedia.org/wiki/Hochschule | V5: 20 | W5: =L5+N5+P5+R5+T5+V5 -> 155 | X5: حداقل 80٪ پاسخ درست در تمرین دو مبحث گرامر؛ استفاده از هر دو ساختار در یک جمله نوشتاری یا گفتاری خودتان؛ خروجی اصلی امروز: خواندن؛ ثبت ۱۵ واژه جدید و خطاها. | Y5: انجام نشد
A6: 2 | B6: 1 | C6: فاز ۱: تثبیت پایه | D6: ='پیگیری پیشرفت'!$B$3+A6-1 -> 46304 | E6: شنیدن | F6: Präteritum: regelmäßige und unregelmäßige Verben (ماضی ساده (Präteritum): افعال باقاعده و بی‌قاعده) | G6: Früher arbeitete er in einer kleinen Firma in Teheran. « او قبلاً در یک شرکت کوچک در تهران کار می‌کرد. » | H6: Als der Strom ausfiel, ging ich sofort in den Keller und schaltete den Generator ein. « وقتی برق قطع شد، بلافاصله به زیرزمین رفتم و ژنراتور را روشن کردم. » | I6: Plusquamperfekt (ماضی بعید) | J6: Nachdem die Techniker die Anlage abgeschaltet hatten, begannen sie mit der Wartung. « پس از آنکه تکنسین‌ها دستگاه را خاموش کرده بودند، تعمیر و نگهداری را شروع کردند. » | K6: Ich hatte schon drei Bewerbungen geschickt, bevor die erste Antwort kam. « پیش از رسیدن اولین پاسخ، من از قبل سه درخواست کار فرستاده بودم. » | L6: 40 | M6: متن مقاله ویکی‌پدیای آلمانی «Wohnungsmarkt» (متن عمومی هم‌موضوع، نه نمونه آزمون): ۲۰ دقیقه بخوانید، ۵ جمله خلاصه بنویسید و ۸ واژه یا ترکیب دشوار را استخراج کنید. 🔗 https://de.wikipedia.org/wiki/Wohnungsmarkt | N6: 20 | O6: همان صفحه ـ Teil 2: مصاحبه رادیویی با یک دانشمند درباره تغذیه و کشاورزی (مصرف گوشت، حشرات، کشاورزی شهری)؛ دو بار؛ پرسش ۱۱ تا ۱۶. 🔗 https://bfu.goethe.de/b2_mod_2MX6/hoeren.php | P6: 40 | Q6: ویدیو: «Redemittel: Die eigene Meinung ausdrücken» (DeutschLera): ۱۰ عبارت را بنویسید و در متن خودتان استفاده کنید. سپس درباره «Gesundheit und Ernährung» بنویسید و ساختار گرامری امروز را به‌کار ببرید: Präteritum. 🔗 https://www.youtube.com/watch?v=Tj9P_HXTBtM | R6: 25 | S6: ویدیو: «Prüfungsvorbereitung B2, Thema präsentieren, Meinung äußern, Redemittel» (Deutsch global). سپس خودتان درباره «Reisen und Verkehr» صحبت کنید و ضبط کنید؛ ساختار گرامری امروز: Plusquamperfekt. 🔗 https://www.youtube.com/watch?v=ILelVsByEPk | T6: 15 | U6: متن مقاله ویکی‌پدیای آلمانی «Mietspiegel»: ۱۵ واژه یا ترکیب دشوار را از آن بیرون بکشید، ‌معنی و حرف تعریف را بنویسید و هر کدام را در یک جمله خودتان به‌کار ببرید. 🔗 https://de.wikipedia.org/wiki/Mietspiegel | V6: 20 | W6: =L6+N6+P6+R6+T6+V6 -> 160 | X6: حداقل 80٪ پاسخ درست در تمرین دو مبحث گرامر؛ استفاده از هر دو ساختار در یک جمله نوشتاری یا گفتاری خودتان؛ خروجی اصلی امروز: شنیدن؛ ثبت ۱۵ واژه جدید و خطاها. | Y6: انجام نشد
A7: 3 | B7: 1 | C7: فاز ۱: تثبیت پایه | D7: ='پیگیری پیشرفت'!$B$3+A7-1 -> 46305 | E7: نوشتن | F7: Futur I: Zukunft und Vermutung (آینده ساده: آینده و حدس) | G7: Nächstes Jahr werde ich in Deutschland arbeiten. « سال آینده در آلمان کار خواهم کرد. » | H7: Er wird wohl noch im Büro sein. « او احتمالاً هنوز در دفتر است. » | I7: Futur II (آینده کامل) | J7: Bis Ende des Jahres werde ich die Prüfung bestanden haben. « تا پایان سال امتحان را گذرانده‌ام. » | K7: Sie wird die Nachricht schon gelesen haben. « او احتمالاً پیام را از قبل خوانده است. » | L7: 40 | M7: همان صفحه ـ Teil 2 «Reisefieber» (مقاله مجله؛ جای‌خالی با جمله؛ ۱۲ دقیقه): جمله‌های مناسب را در جای‌خالی‌ها بگذارید. 🔗 https://bfu.goethe.de/b2_mod_2MX6/lesen.php | N7: 15 | O7: همان صفحه ـ Teil 3: گفت‌وگوی رادیویی درباره شیوه‌های زندگی جایگزین (WG، خانه سالمندان)؛ یک بار؛ تطبیق گوینده و جمله. 🔗 https://bfu.goethe.de/b2_mod_2MX6/hoeren.php | P7: 15 | Q7: ویدیو: «Sofort besser schreiben mit diesen Konnektoren! (b2, c1)» (DeutschLera): حداقل ۶ حرف ربط را در متنتان به‌کار ببرید. سپس درباره «Technik und Energie» بنویسید و ساختار گرامری امروز را به‌کار ببرید: Futur I. 🔗 https://www.youtube.com/watch?v=oBqzMHsZfPA | R7: 45 | S7: ویدیو: «Was Prüfer bei der BILDBESCHREIBUNG erwarten: ÖSD B2» (AR German Talks): معیارهای ارزیابی را یادداشت کنید. سپس خودتان درباره «Wirtschaft und Finanzen» صحبت کنید و ضبط کنید؛ ساختار گرامری امروز: Futur II. 🔗 https://www.youtube.com/watch?v=Xwp5L53uj3s | T7: 20 | U7: متن مقاله ویکی‌پدیای آلمانی «Familie»: ۱۵ واژه یا ترکیب دشوار را از آن بیرون بکشید، ‌معنی و حرف تعریف را بنویسید و هر کدام را در یک جمله خودتان به‌کار ببرید. 🔗 https://de.wikipedia.org/wiki/Familie | V7: 20 | W7: =L7+N7+P7+R7+T7+V7 -> 155 | X7: حداقل 80٪ پاسخ درست در تمرین دو مبحث گرامر؛ استفاده از هر دو ساختار در یک جمله نوشتاری یا گفتاری خودتان؛ خروجی اصلی امروز: نوشتن؛ ثبت ۱۵ واژه جدید و خطاها. | Y7: انجام نشد
A8: 4 | B8: 1 | C8: فاز ۱: تثبیت پایه | D8: ='پیگیری پیشرفت'!$B$3+A8-1 -> 46306 | E8: گفتار | F8: Trennbare und untrennbare Verben (افعال جداشدنی و جدانشدنی) | G8: Ich rufe morgen den Vermieter an und teile ihm meinen Einzugstermin mit. « فردا به صاحب‌خانه زنگ می‌زنم و زمان نقل‌مکانم را به او اطلاع می‌دهم. » | H8: Der Ingenieur versteht das Problem und erklärt es seinen Kollegen. « مهندس مشکل را می‌فهمد و آن را برای همکارانش توضیح می‌دهد. » | I8: Reflexive Verben und Reflexivpronomen (افعال انعکاسی و ضمایر انعکاسی) | J8: Ich interessiere mich für erneuerbare Energien. « من به انرژی‌های تجدیدپذیر علاقه دارم. » | K8: Wir haben uns lange über die neuen Sicherheitsvorschriften unterhalten. « ما مدت طولانی درباره مقررات ایمنی جدید گفتگو کردیم. » | L8: 40 | M8: متن مقاله ویکی‌پدیای آلمانی «Synchrotron» (متن عمومی هم‌موضوع، نه نمونه آزمون): ۲۰ دقیقه بخوانید، ۵ جمله خلاصه بنویسید و ۸ واژه یا ترکیب دشوار را استخراج کنید. 🔗 https://de.wikipedia.org/wiki/Synchrotron | N8: 25 | O8: همان صفحه ـ Teil 4: سخنرانی کوتاه «Bessere Arbeitstechniken» (تمرکز، استراحت، فشار زمان)؛ دو بار؛ ۸ تکلیف. 🔗 https://bfu.goethe.de/b2_mod_2MX6/hoeren.php | P8: 20 | Q8: ویدیو: «Deutsch lernen: B2 Beschwerdebrief schreiben» (SimplyDeutsch): نامه شکایت را طبق همین الگو بنویسید. سپس درباره «Konsum und Werbung» بنویسید و ساختار گرامری امروز را به‌کار ببرید: Trennbare und untrennbare Verben. 🔗 https://www.youtube.com/watch?v=fJi5dHkeOs8 | R8: 15 | S8: ویدیو: «ÖSD B2 – Sprechen – Aufgabe 2 – Ein Bild/Foto beschreiben und interpretieren» (نوای یار). سپس خودتان درباره «Arbeit und Beruf» صحبت کنید و ضبط کنید؛ ساختار گرامری امروز: Reflexive Verben und Reflexivpronomen. 🔗 https://www.youtube.com/watch?v=sSlVy6IXTME | T8: 40 | U8: متن مقاله ویکی‌پدیای آلمانی «Teilchenbeschleuniger»: ۱۵ واژه یا ترکیب دشوار را از آن بیرون بکشید، ‌معنی و حرف تعریف را بنویسید و هر کدام را در یک جمله خودتان به‌کار ببرید. 🔗 https://de.wikipedia.org/wiki/Teilchenbeschleuniger | V8: 20 | W8: =L8+N8+P8+R8+T8+V8 -> 160 | X8: حداقل 80٪ پاسخ درست در تمرین دو مبحث گرامر؛ استفاده از هر دو ساختار در یک جمله نوشتاری یا گفتاری خودتان؛ خروجی اصلی امروز: گفتار؛ ثبت ۱۵ واژه جدید و خطاها. | Y8: انجام نشد
A9: 5 | B9: 1 | C9: فاز ۱: تثبیت پایه | D9: ='پیگیری پیشرفت'!$B$3+A9-1 -> 46307 | E9: خواندن و شنیدن | F9: Verben mit Präposition und Akkusativ (افعال با حرف اضافه و مفعول در حالت اکوزاتیو) | G9: Er wartet auf die Genehmigung der Behörde. « او منتظر مجوز اداره است. » | H9: Ich habe mich über das Jobangebot sehr gefreut. « من از پیشنهاد شغلی بسیار خوشحال شدم. » | I9: Verben mit Präposition und Dativ (افعال با حرف اضافه و مفعول در حالت داتیو) | J9: Sie beschäftigt sich seit Jahren mit der Hochspannungstechnik. « او سال‌هاست با فناوری فشار قوی سروکار دارد. » | K9: Ich zweifle nicht an deinen Fähigkeiten. « من به توانایی‌های تو شک ندارم. » | L9: 40 | M9: همان صفحه ـ Teil 3 «Doktor Google» (مقاله روزنامه؛ چندگزینه‌ای؛ ۱۲ دقیقه): ۶ پرسش را پاسخ دهید و دلیل هر پاسخ را از متن نشان دهید. 🔗 https://bfu.goethe.de/b2_mod_2MX6/lesen.php | N9: 35 | O9: فایل صوتی رسمی گوته B2 (جوانان) Prüfungstraining 1 Hören (MP3): به‌همراه PDF همان نمونه‌آزمون حل کنید. 🔗 https://goethemp4s.akamaized.net/resources/files/mp310/pruefungstraining_1_hoeren_b2_jugendliche.mp3 | P9: 35 | Q9: ویدیو: «ÖSD Zertifikat B2 | Schreiben 1 | Beschwerde | Jobbörse vermittelt Praktikum» (Deutsch mit Christiane): نمونه واقعی ÖSD؛ ابتدا خودتان بنویسید، سپس ویدیو را ببینید. سپس درباره «Kultur und Freizeit» بنویسید و ساختار گرامری امروز را به‌کار ببرید: Verben mit Präposition und Akkusativ. 🔗 https://www.youtube.com/watch?v=CFo_Njg5qtk | R9: 20 | S9: ویدیو: «ÖSD b2 (Fotobeschreibung)» (Deutsch mit Melissa). سپس خودتان درباره «Gesundheit und Ernährung» صحبت کنید و ضبط کنید؛ ساختار گرامری امروز: Verben mit Präposition und Dativ. 🔗 https://www.youtube.com/watch?v=fokI7H-Ufsc | T9: 15 | U9: متن مقاله ویکی‌پدیای آلمانی «Datenschutz»: ۱۵ واژه یا ترکیب دشوار را از آن بیرون بکشید، ‌معنی و حرف تعریف را بنویسید و هر کدام را در یک جمله خودتان به‌کار ببرید. 🔗 https://de.wikipedia.org/wiki/Datenschutz | V9: 20 | W9: =L9+N9+P9+R9+T9+V9 -> 165 | X9: حداقل 80٪ پاسخ درست در تمرین دو مبحث گرامر؛ استفاده از هر دو ساختار در یک جمله نوشتاری یا گفتاری خودتان؛ خروجی اصلی امروز: خواندن و شنیدن؛ ثبت ۱۵ واژه جدید و خطاها. | Y9: انجام نشد
A10: 6 | B10: 1 | C10: فاز ۱: تثبیت پایه | D10: ='پیگیری پیشرفت'!$B$3+A10-1 -> 46308 | E10: نوشتن و گفتار | F10: Pronominaladverbien: darauf, wofür, damit (قیدهای ضمیری: darauf، wofür، damit) | G10: Worauf wartest du? – Darauf, dass der Techniker endlich kommt. « منتظر چه هستی؟ – منتظر اینکه تکنسین بالاخره بیاید. » | H10: Ich habe mich darum gekümmert, dass alle Unterlagen vollständig sind. « من رسیدگی کردم که همه مدارک کامل باشند. » | I10: Modalverben im Präsens und Präteritum (افعال کمکی وجهی در حال و ماضی ساده) | J10: Man darf die Anlage nur mit Schutzkleidung betreten. « فقط با لباس ایمنی اجازه ورود به تأسیسات وجود دارد. » | K10: Als Kind musste ich jeden Tag eine Stunde zur Schule laufen. « در کودکی مجبور بودم هر روز یک ساعت تا مدرسه پیاده بروم. » | L10: 40 | M10: متن مقاله ویکی‌پدیای آلمانی «Migration» (متن عمومی هم‌موضوع، نه نمونه آزمون): ۲۰ دقیقه بخوانید، ۵ جمله خلاصه بنویسید و ۸ واژه یا ترکیب دشوار را استخراج کنید. 🔗 https://de.wikipedia.org/wiki/Migration | N10: 15 | O10: فایل رسمی گوته B2 (بزرگسالان) Modellsatz Hören/Rahmen (MP4): فایل را همراه PDF نمونه‌آزمون پخش کنید. 🔗 https://goethemp4s.akamaized.net/resources/files/mp477/b2_modellsatz_rahmen_erwachsene.mp4 | P10: 20 | Q10: ویدیو: «ÖSD Zertifikat B2 | Schreiben 1 | Beschwerde über Fahrradverleih» (Deutsch mit Christiane): نمونه واقعی ÖSD. سپس درباره «Umwelt und Klima» بنویسید و ساختار گرامری امروز را به‌کار ببرید: Pronominaladverbien. 🔗 https://www.youtube.com/watch?v=jPxFBXCdm_Y | R10: 40 | S10: ویدیو: «Mündlich B2 ÖSD ـ Bild beschreiben» (Deutsch B2,C1): مدل توصیف تصویر. سپس خودتان درباره «Technik und Energie» صحبت کنید و ضبط کنید؛ ساختار گرامری امروز: Modalverben im Präsens und Präteritum. 🔗 https://www.youtube.com/watch?v=GFsneyjtKjA | T10: 30 | U10: متن مقاله ویکی‌پدیای آلمانی «Integration (Soziologie)»: ۱۵ واژه یا ترکیب دشوار را از آن بیرون بکشید، ‌معنی و حرف تعریف را بنویسید و هر کدام را در یک جمله خودتان به‌کار ببرید. 🔗 https://de.wikipedia.org/wiki/Integration_(Soziologie) | V10: 20 | W10: =L10+N10+P10+R10+T10+V10 -> 165 | X10: حداقل 80٪ پاسخ درست در تمرین دو مبحث گرامر؛ استفاده از هر دو ساختار در یک جمله نوشتاری یا گفتاری خودتان؛ خروجی اصلی امروز: نوشتن و گفتار؛ ثبت ۱۵ واژه جدید و خطاها. | Y10: انجام نشد
A11: 7 | B11: 1 | C11: فاز ۱: تثبیت پایه | D11: ='پیگیری پیشرفت'!$B$3+A11-1 -> 46309 | E11: مرور هفته و آزمون | F11: Modalverben im Perfekt (Ersatzinfinitiv) (افعال وجهی در ماضی نقلی (مصدر جایگزین)) | G11: Wir haben gestern bis spät arbeiten müssen. « ما دیروز مجبور شدیم تا دیر وقت کار کنیم. » | H11: Sie hat leider nicht kommen können, weil sie krank war. « او متأسفانه نتوانست بیاید، چون بیمار بود. » | I11: Subjektive Bedeutung der Modalverben (معنای ذهنی (احتمال و نقل‌قول) افعال وجهی) | J11: Er muss sehr müde sein, er gähnt die ganze Zeit. « او حتماً خیلی خسته است، تمام مدت خمیازه می‌کشد. » | K11: Sie soll angeblich in Berlin studiert haben. « گفته می‌شود که او در برلین تحصیل کرده است. » | L11: 40 | M11: مرور خطاهای خواندن این هفته: هر تکلیف اشتباه را دوباره بخوانید و علت خطا را بنویسید. (مرور هفته 1) منبع: صفحه رسمی دانلودهای ÖSD: یکی از مدل‌ست‌ها را انتخاب کنید و خطاهای این هفته را دوباره حل کنید. 🔗 https://www.osd.at/downloads/ | N11: 30 | O11: مرور خطاهای شنیداری: بخش‌هایی را که اشتباه شنیده‌اید دوباره گوش دهید و با متن تطبیق دهید. (مرور هفته 1) منبع: صفحه رسمی گوته ـ هر Teil شنیداری را که این هفته ضعیف بوده دوباره گوش دهید. 🔗 https://bfu.goethe.de/b2_mod_2MX6/hoeren.php | P11: 30 | Q11: یکی از نوشته‌های هفته را بازنویسی کنید و فهرست خطاهای تکراری خود را به‌روز کنید. (مرور هفته 1) منبع: LanguageTool: یکی از نوشته‌های این هفته را بررسی کنید و خطاهای تکراری را فهرست کنید. 🔗 https://languagetool.org/de | R11: 30 | S11: ضبط یک تک‌گویی ۳ دقیقه‌ای درباره موضوعی از همین هفته؛ بازشنیدن و یادداشت ۳ نقطه ضعف. (مرور هفته 1) منبع: ویدیوی رسمی ÖSD درباره Sprechen: بازبینی معیارها و ضبط یک تک‌گویی ۳ دقیقه‌ای. 🔗 https://www.youtube.com/watch?v=nFQljN4Oeio | T11: 20 | U11: مرور همه واژه‌های دشوار هفته با کارت‌های مرور و جمله‌سازی شفاهی. (مرور هفته 1) منبع: فرهنگ لغت DWDS 🔗 https://www.dwds.de/ | V11: 20 | W11: =L11+N11+P11+R11+T11+V11 -> 170 | X11: همه خطاهای هفته را در دفتر خطا مرور کنید؛ هر خطا را دوباره درست بنویسید و ۱۰ جمله جدید با گرامرهای هفته بسازید. | Y11: انجام نشد
A12: 8 | B12: 2 | C12: فاز ۱: تثبیت پایه | D12: ='پیگیری پیشرفت'!$B$3+A12-1 -> 46310 | E12: خواندن | F12: Vorgangspassiv im Präsens (مجهول فرایندی در زمان حال) | G12: Der Generator wird jede Woche kontrolliert. « ژنراتور هر هفته بازرسی می‌شود. » | H12: In der Werkstatt werden die Kabel getestet. « در کارگاه کابل‌ها آزمایش می‌شوند. » | I12: Vorgangspassiv im Präteritum (مجهول فرایندی در ماضی ساده) | J12: Das Gebäude wurde 1998 gebaut. « این ساختمان در سال ۱۹۹۸ ساخته شد. » | K12: Die Messdaten wurden gestern automatisch gespeichert. « داده‌های اندازه‌گیری دیروز به‌طور خودکار ذخیره شدند. » | L12: 40 | M12: همان صفحه ـ Teil 4 «Digitale Nomaden» (نظر خوانندگان و تطبیق با تیتر؛ ۱۲ دقیقه). 🔗 https://bfu.goethe.de/b2_mod_2MX6/lesen.php | N12: 40 | O12: ویدیو: «ÖSD MITTELSTUFE B2 ـ Hören Modell 3 Teil 1 mit Lösung» (DEUTSCH-INSTITUT). 🔗 https://www.youtube.com/watch?v=XwuOjYe-J3o | P12: 20 | Q12: ویدیو: «ÖSD B2 Schreiben: Formelle E-Mail & Meinung schreiben | 10 Modelltests erklärt» (Lernen Deutsch Prüfung). سپس درباره «Reisen und Verkehr» بنویسید و ساختار گرامری امروز را به‌کار ببرید: Vorgangspassiv im Präsens. 🔗 https://www.youtube.com/watch?v=DjTHZa4pb2c | R12: 20 | S12: ویدیو: «Deutsch lernen: Bildbeschreibung (Mündliche Prüfung) A1–B2» (SimplyDeutsch). سپس خودتان درباره «Wissenschaft und Forschung» صحبت کنید و ضبط کنید؛ ساختار گرامری امروز: Vorgangspassiv im Präteritum. 🔗 https://www.youtube.com/watch?v=krJml8rJr8M | T12: 15 | U12: متن مقاله ویکی‌پدیای آلمانی «Museum»: ۱۵ واژه یا ترکیب دشوار را از آن بیرون بکشید، ‌معنی و حرف تعریف را بنویسید و هر کدام را در یک جمله خودتان به‌کار ببرید. 🔗 https://de.wikipedia.org/wiki/Museum | V12: 20 | W12: =L12+N12+P12+R12+T12+V12 -> 155 | X12: حداقل 80٪ پاسخ درست در تمرین دو مبحث گرامر؛ استفاده از هر دو ساختار در یک جمله نوشتاری یا گفتاری خودتان؛ خروجی اصلی امروز: خواندن؛ ثبت ۱۵ واژه جدید و خطاها. | Y12: انجام نشد
A13: 9 | B13: 2 | C13: فاز ۱: تثبیت پایه | D13: ='پیگیری پیشرفت'!$B$3+A13-1 -> 46311 | E13: شنیدن | F13: Vorgangspassiv im Perfekt und Plusquamperfekt (مجهول فرایندی در ماضی نقلی و بعید) | G13: Die Anlage ist letzte Woche repariert worden. « دستگاه هفته گذشته تعمیر شده است. » | H13: Nachdem die Fehler gefunden worden waren, startete man das System neu. « پس از آنکه خطاها پیدا شده بودند، سیستم دوباره راه‌اندازی شد. » | I13: Passiv mit Modalverben (مجهول با افعال وجهی) | J13: Die Wartung muss regelmäßig durchgeführt werden. « تعمیر و نگهداری باید به‌طور منظم انجام شود. » | K13: Der Bericht konnte nicht rechtzeitig abgegeben werden. « گزارش نتوانست به‌موقع تحویل داده شود. » | L13: 40 | M13: متن مقاله ویکی‌پدیای آلمانی «Klimawandel» (متن عمومی هم‌موضوع، نه نمونه آزمون): ۲۰ دقیقه بخوانید، ۵ جمله خلاصه بنویسید و ۸ واژه یا ترکیب دشوار را استخراج کنید. 🔗 https://de.wikipedia.org/wiki/Klimawandel | N13: 20 | O13: ویدیو: «Projekt ÖSD B2: Hörverstehen T1-1 | Prüfungsvorbereitung & Lösungen» (Lernen Deutsch Prüfung). 🔗 https://www.youtube.com/watch?v=L6wl89TFx-Y | P13: 40 | Q13: ویدیو: «Korrektur eines Leserbriefs (Besser Deutsch schreiben B2)» (Deutsch mit Rieke): متن خودتان را با همان معیارها اصلاح کنید. سپس درباره «Wirtschaft und Finanzen» بنویسید و ساختار گرامری امروز را به‌کار ببرید: Vorgangspassiv im Perfekt und Plusquamperfekt. 🔗 https://www.youtube.com/watch?v=LgHtgyiuv8A | R13: 25 | S13: ویدیو: «ÖSD B2 – Sprechen – Aufgabe 3 – Meinungsaustausch / Diskussion» (نوای یار). سپس خودتان درباره «Medien und Internet» صحبت کنید و ضبط کنید؛ ساختار گرامری امروز: Passiv mit Modalverben. 🔗 https://www.youtube.com/watch?v=jjTeXSmVj_Y | T13: 15 | U13: متن مقاله ویکی‌پدیای آلمانی «Treibhauseffekt»: ۱۵ واژه یا ترکیب دشوار را از آن بیرون بکشید، ‌معنی و حرف تعریف را بنویسید و هر کدام را در یک جمله خودتان به‌کار ببرید. 🔗 https://de.wikipedia.org/wiki/Treibhauseffekt | V13: 20 | W13: =L13+N13+P13+R13+T13+V13 -> 160 | X13: حداقل 80٪ پاسخ درست در تمرین دو مبحث گرامر؛ استفاده از هر دو ساختار در یک جمله نوشتاری یا گفتاری خودتان؛ خروجی اصلی امروز: شنیدن؛ ثبت ۱۵ واژه جدید و خطاها. | Y13: انجام نشد
A14: 10 | B14: 2 | C14: فاز ۱: تثبیت پایه | D14: ='پیگیری پیشرفت'!$B$3+A14-1 -> 46312 | E14: نوشتن | F14: Passiv im Futur (مجهول در زمان آینده) | G14: Das neue System wird nächsten Monat installiert werden. « سیستم جدید ماه آینده نصب خواهد شد. » | H14: Die Ergebnisse werden morgen veröffentlicht werden. « نتایج فردا منتشر خواهند شد. » | I14: Zustandspassiv (مجهول حالتی (نتیجه)) | J14: Das Werkstor ist ab 18 Uhr geschlossen. « دروازه کارگاه از ساعت ۱۸ بسته است. » | K14: Die Maschine ist bereits repariert, wir können weiterarbeiten. « دستگاه از قبل تعمیر شده است، می‌توانیم به کار ادامه دهیم. » | L14: 40 | M14: همان صفحه ـ Teil 5 «Studienordnung Theaterwissenschaft» (مقررات؛ تطبیق تیتر؛ ۶ دقیقه): این نوع متن اداری را باید در آزمون هم سریع بخوانید. 🔗 https://bfu.goethe.de/b2_mod_2MX6/lesen.php | N14: 15 | O14: ویدیو: «ÖSD B2 Hörverstehen: Test 2, Aufgabe 1 mit Lösungen» (Lernen Deutsch Prüfung). 🔗 https://www.youtube.com/watch?v=MpdaniZohao | P14: 15 | Q14: ویدیو: «MEINUNG ÄUSSERN / REDEMITTEL (mündliche und schriftliche Prüfung)» (Dein Sprachcoach). سپس درباره «Arbeit und Beruf» بنویسید و ساختار گرامری امروز را به‌کار ببرید: Passiv im Futur. 🔗 https://www.youtube.com/watch?v=m9N-q74a5iE | R14: 45 | S14: ویدیو: «ÖSD-Prüfung B2, Mündlich Teil 3: Meinungsaustausch» (Deutsch global). سپس خودتان درباره «Migration und Integration» صحبت کنید و ضبط کنید؛ ساختار گرامری امروز: Zustandspassiv. 🔗 https://www.youtube.com/watch?v=PJQGfpXbMVI | T14: 20 | U14: متن مقاله ویکی‌پدیای آلمانی «Bologna-Prozess»: ۱۵ واژه یا ترکیب دشوار را از آن بیرون بکشید، ‌معنی و حرف تعریف را بنویسید و هر کدام را در یک جمله خودتان به‌کار ببرید. 🔗 https://de.wikipedia.org/wiki/Bologna-Prozess | V14: 20 | W14: =L14+N14+P14+R14+T14+V14 -> 155 | X14: حداقل 80٪ پاسخ درست در تمرین دو مبحث گرامر؛ استفاده از هر دو ساختار در یک جمله نوشتاری یا گفتاری خودتان؛ خروجی اصلی امروز: نوشتن؛ ثبت ۱۵ واژه جدید و خطاها. | Y14: انجام نشد
A15: 11 | B15: 2 | C15: فاز ۱: تثبیت پایه | D15: ='پیگیری پیشرفت'!$B$3+A15-1 -> 46313 | E15: گفتار | F15: Passiversatzformen: man und sich lassen (جانشین‌های مجهول: man و sich lassen) | G15: Diese Aufgabe lässt sich leicht lösen. « این مسئله به‌راحتی حل می‌شود. » | H15: Den Fehler kann man sofort erkennen. « خطا را می‌توان بلافاصله تشخیص داد. » | I15: Passiversatz: sein + zu + Infinitiv (جانشین مجهول: sein + zu + مصدر) | J15: Die Sicherheitsregeln sind unbedingt zu beachten. « قوانین ایمنی حتماً باید رعایت شوند. » | K15: Der Fehler ist leicht zu beheben. « این خطا به‌آسانی قابل رفع است. » | L15: 40 | M15: متن مقاله ویکی‌پدیای آلمانی «Stadtplanung» (متن عمومی هم‌موضوع، نه نمونه آزمون): ۲۰ دقیقه بخوانید، ۵ جمله خلاصه بنویسید و ۸ واژه یا ترکیب دشوار را استخراج کنید. 🔗 https://de.wikipedia.org/wiki/Stadtplanung | N15: 25 | O15: ویدیو: «ÖSD B2 Modelltest 8 Aufgabe 2 Hören mit Lösungen» (Lernen Deutsch Prüfung). 🔗 https://www.youtube.com/watch?v=YJAwhjgQVHE | P15: 20 | Q15: ویدیو: «Redemittel: EIGENE MEINUNG ÄUßERN / DISKUSSION (B2, C1, C2)» (Richtig Deutsch sprechen). سپس درباره «Gesundheit und Ernährung» بنویسید و ساختار گرامری امروز را به‌کار ببرید: Passiversatzformen. 🔗 https://www.youtube.com/watch?v=7gAG0tXjlzM | R15: 15 | S15: صفحه رسمی گوته B2 ـ Sprechen Teil 1 (سخنرانی ۴ دقیقه‌ای): یکی از موضوع‌ها را انتخاب کنید: «Finanzierung des Studiums»، «Gesund leben»، «Freundschaften pflegen» یا «Ernährung am Arbeitsplatz». ضبط کنید. سپس خودتان درباره «Reisen und Verkehr» صحبت کنید و ضبط کنید؛ ساختار گرامری امروز: Passiversatz. 🔗 https://bfu.goethe.de/b2_mod_2MX6/sprechen.php | T15: 40 | U15: متن مقاله ویکی‌پدیای آلمانی «Gentrifizierung»: ۱۵ واژه یا ترکیب دشوار را از آن بیرون بکشید، ‌معنی و حرف تعریف را بنویسید و هر کدام را در یک جمله خودتان به‌کار ببرید. 🔗 https://de.wikipedia.org/wiki/Gentrifizierung | V15: 20 | W15: =L15+N15+P15+R15+T15+V15 -> 160 | X15: حداقل 80٪ پاسخ درست در تمرین دو مبحث گرامر؛ استفاده از هر دو ساختار در یک جمله نوشتاری یا گفتاری خودتان؛ خروجی اصلی امروز: گفتار؛ ثبت ۱۵ واژه جدید و خطاها. | Y15: انجام نشد
A16: 12 | B16: 2 | C16: فاز ۱: تثبیت پایه | D16: ='پیگیری پیشرفت'!$B$3+A16-1 -> 46314 | E16: خواندن و شنیدن | F16: Passiversatz: Adjektive auf -bar und -lich (جانشین مجهول: صفت‌های دارای -bar و -lich) | G16: Diese Aufgabe ist lösbar, wenn man genug Zeit hat. « این مسئله حل‌شدنی است، اگر زمان کافی داشته باشید. » | H16: Die Kosten sind vermeidbar, wenn man rechtzeitig plant. « اگر به‌موقع برنامه‌ریزی شود، هزینه‌ها قابل اجتناب‌اند. » | I16: Unpersönliches Passiv (Passiv ohne Subjekt) (مجهول بی‌فاعل (غیرشخصی)) | J16: Hier wird nicht geraucht. « اینجا سیگار کشیده نمی‌شود. » | K16: In der Pause wurde viel gelacht. « در زنگ تفریح زیاد خندیده شد. » | L16: 40 | M16: PDF رسمی نمونه‌آزمون گوته B2 (جوانان) ـ Lesen Teil 1: چهار نفر در انجمن درباره تعطیلاتشان می‌نویسند؛ تطبیق جمله‌ها با افراد. 🔗 https://www.goethe.de/resources/files/pdf206/b2-jugendliche-modellsatz-1.2_tahoma132.pdf | N16: 35 | O16: ویدیو: «Ösd Mittelstufe B2 Modelltest 10 Hören Teil 2 mit Lösungen» (DEUTSCH-INSTITUT). 🔗 https://www.youtube.com/watch?v=LYeBgund6SI | P16: 35 | Q16: ویدیو: «Redemittel Meinung zustimmen/ablehnen, B1/B2 (Diskussion)» (SimplyDeutsch). سپس درباره «Technik und Energie» بنویسید و ساختار گرامری امروز را به‌کار ببرید: Passiversatz. 🔗 https://www.youtube.com/watch?v=Veb-oo1lJQM | R16: 20 | S16: همان صفحه ـ Teil 2 (بحث ۵ دقیقه‌ای): «Sollen Studierende ihre Professorinnen und Professoren beurteilen?» ـ موافق و مخالف را با شریک یا ضبط صدا تمرین کنید. سپس خودتان درباره «Wirtschaft und Finanzen» صحبت کنید و ضبط کنید؛ ساختار گرامری امروز: Unpersönliches Passiv (Passiv ohne Subjekt). 🔗 https://bfu.goethe.de/b2_mod_2MX6/sprechen.php | T16: 15 | U16: متن مقاله ویکی‌پدیای آلمانی «Demografischer Wandel»: ۱۵ واژه یا ترکیب دشوار را از آن بیرون بکشید، ‌معنی و حرف تعریف را بنویسید و هر کدام را در یک جمله خودتان به‌کار ببرید. 🔗 https://de.wikipedia.org/wiki/Demografischer_Wandel | V16: 20 | W16: =L16+N16+P16+R16+T16+V16 -> 165 | X16: حداقل 80٪ پاسخ درست در تمرین دو مبحث گرامر؛ استفاده از هر دو ساختار در یک جمله نوشتاری یا گفتاری خودتان؛ خروجی اصلی امروز: خواندن و شنیدن؛ ثبت ۱۵ واژه جدید و خطاها. | Y16: انجام نشد
... A74: 70 | B74: 10 | C74: فاز ۳: شبیه‌سازی و صیقل | D74: ='پیگیری پیشرفت'!$B$3+A74-1 -> 46372 | E74: آزمون آزمایشی | F74: Adjektivendungen: Gesamtüberblick mit Komparation (پایان صفت‌ها: مرور جامع همراه با درجه‌بندی) | G74: Mit seinen langjährigen Erfahrungen in der Hochspannungstechnik ist er ein gefragter Spezialist. « با تجربه‌های چندین‌ساله‌اش در فناوری فشار قوی، او متخصصی پرتقاضاست. » | H74: Wir suchen einen zuverlässigeren Kollegen für unser engagiertes Team. « ما دنبال همکاری قابل‌اعتمادتر برای تیم پرانگیزه‌مان هستیم. » | I74: Typische Fehler: Kasus, Genus und Verbposition (خطاهای رایج: حالت، جنسیت و جایگاه فعل) | J74: Falsch: Ich warte für den Bus. – Richtig: Ich warte auf den Bus. « نادرست: «Ich warte für den Bus». درست: «Ich warte auf den Bus» (من منتظر اتوبوس هستم). » | K74: Falsch: Weil er ist krank, bleibt er zu Hause. – Richtig: Weil er krank ist, bleibt er zu Hause. « نادرست: فعل در جمله وابسته در جای دوم. درست: فعل در پایان جمله وابسته می‌آید (چون او بیمار است، در خانه می‌ماند). » | L74: 20 | M74: آزمون آزمایشی 6 ـ خواندن: همه تکلیف‌ها را در ۹۰ دقیقه و بدون فرهنگ لغت حل کنید. منبع: مدل‌ست رسمی «ÖSD Zertifikat B2 PMB» (ZIP؛ ویژه حرفه‌های پرستاری/پزشکی، قالب مشابه)؛ بخش Lesen؛ آخرین تمرین زمان‌دار. 🔗 https://osd.at/wp-content/uploads/2026/08/ZB2_PMB_Modellsatz.zip | N74: 90 | O74: آزمون آزمایشی 6 ـ شنیدن: مطابق شرایط آزمون و هر فایل صوتی فقط یک بار (حدود ۳۰ دقیقه؛ مدت دقیق را با نمونه رسمی تطبیق دهید). منبع: همان ZIP ـ بخش Hören. 🔗 https://osd.at/wp-content/uploads/2026/08/ZB2_PMB_Modellsatz.zip | P74: 30 | Q74: آزمون آزمایشی 6 ـ نوشتن: همه تکلیف‌ها را در ۹۰ دقیقه بنویسید؛ سپس با معیارهای محتوا، ساختار، واژگان و صحت دستوری ارزیابی کنید. منبع: همان ZIP ـ بخش Schreiben. 🔗 https://osd.at/wp-content/uploads/2026/08/ZB2_PMB_Modellsatz.zip | R74: 90 | S74: آزمون آزمایشی 6 ـ گفتار: ۱۵ تا ۲۰ دقیقه با شریک یا معلم (یا ضبط صدا) و بازشنیدن ضبط. منبع: همان ZIP ـ بخش Sprechen؛ شبیه‌سازی نهایی. 🔗 https://osd.at/wp-content/uploads/2026/08/ZB2_PMB_Modellsatz.zip | T74: 20 | U74: مرور خطاهای آزمون: ۱۰ واژه یا عبارتی را که در آزمون ندانستید مرور کنید. منبع: فرهنگ لغت DWDS برای مرور واژه‌های دشوار آزمون 🔗 https://www.dwds.de/ | V74: 10 | W74: =L74+N74+P74+R74+T74+V74 -> 260 | X74: آزمون آزمایشی شماره 6 را در شرایط واقعی انجام دهید، نمره هر مهارت را در برگه «آزمون‌های آزمایشی» ثبت کنید و ضعیف‌ترین مهارت را مشخص کنید. | Y74: انجام نشد
A75: جمع کل | L75: =SUM(L5:L74) -> 2680 | N75: =SUM(N5:N74) -> 2160 | P75: =SUM(P5:P74) -> 1800 | R75: =SUM(R5:R74) -> 2310 | T75: =SUM(T5:T74) -> 1550 | V75: =SUM(V5:V74) -> 1340 | W75: =SUM(W5:W74) -> 11840 | X75: =TEXT(W75/60,"0.0")&" ساعت مطالعه در کل ۷۰ روز" -> 197.3 ساعت مطالعه در کل ۷۰ روز

Sheet فهرست گرامر B2
A1: فهرست کامل مباحث گرامر برای B2 و جایگاه آن‌ها در برنامه
A2: هر مبحث دست‌کم یک بار در برنامه آمده است. مباحث دشوار در هفته دهم (روزهای ۶۴ تا ۷۰) یک بار دیگر به‌صورت جامع مرور می‌شوند. ستون «ارزیابی من» را پس از هر مرور به‌روز کنید؛ مباحث «ضعیف» را در روزهای مرور اولویت بدهید.
A4: ردیف | B4: دسته (هفته) | C4: مبحث گرامری (آلمانی و فارسی) | D4: سطح دشواری | E4: روز در برنامه | F4: روز مرور جامع | G4: ارزیابی من
A5: 1 | B5: فعل و زمان‌ها (هفته 1) | C5: Präsens: starke und unregelmäßige Verben (زمان حال: افعال قوی و بی‌قاعده) | D5: آسان | E5: 1 | F5: 69 | G5: ارزیابی نشده
A6: 2 | B6: فعل و زمان‌ها (هفته 1) | C6: Perfekt mit haben und sein (ماضی نقلی با haben و sein) | D6: آسان | E6: 1 | F6: 69 | G6: ارزیابی نشده
A7: 3 | B7: فعل و زمان‌ها (هفته 1) | C7: Präteritum: regelmäßige und unregelmäßige Verben (ماضی ساده (Präteritum): افعال باقاعده و بی‌قاعده) | D7: آسان | E7: 2 | F7: 69 | G7: ارزیابی نشده
A8: 4 | B8: فعل و زمان‌ها (هفته 1) | C8: Plusquamperfekt (ماضی بعید) | D8: متوسط | E8: 2 | F8: 69 | G8: ارزیابی نشده
A9: 5 | B9: فعل و زمان‌ها (هفته 1) | C9: Futur I: Zukunft und Vermutung (آینده ساده: آینده و حدس) | D9: متوسط | E9: 3 | F9: 69 | G9: ارزیابی نشده
A10: 6 | B10: فعل و زمان‌ها (هفته 1) | C10: Futur II (آینده کامل) | D10: متوسط | E10: 3 | F10: 69 | G10: ارزیابی نشده
A11: 7 | B11: فعل و زمان‌ها (هفته 1) | C11: Trennbare und untrennbare Verben (افعال جداشدنی و جدانشدنی) | D11: آسان | E11: 4 | F11: — | G11: ارزیابی نشده
A12: 8 | B12: فعل و زمان‌ها (هفته 1) | C12: Reflexive Verben und Reflexivpronomen (افعال انعکاسی و ضمایر انعکاسی) | D12: آسان | E12: 4 | F12: — | G12: ارزیابی نشده
A13: 9 | B13: فعل و زمان‌ها (هفته 1) | C13: Verben mit Präposition und Akkusativ (افعال با حرف اضافه و مفعول در حالت اکوزاتیو) | D13: متوسط | E13: 5 | F13: 68 | G13: ارزیابی نشده
A14: 10 | B14: فعل و زمان‌ها (هفته 1) | C14: Verben mit Präposition und Dativ (افعال با حرف اضافه و مفعول در حالت داتیو) | D14: متوسط | E14: 5 | F14: 68 | G14: ارزیابی نشده
A15: 11 | B15: فعل و زمان‌ها (هفته 1) | C15: Pronominaladverbien: darauf, wofür, damit (قیدهای ضمیری: darauf، wofür، damit) | D15: متوسط | E15: 6 | F15: 68 | G15: ارزیابی نشده
A16: 12 | B16: فعل و زمان‌ها (هفته 1) | C16: Modalverben im Präsens und Präteritum (افعال کمکی وجهی در حال و ماضی ساده) | D16: متوسط | E16: 6 | F16: 68 | G16: ارزیابی نشده
A17: 13 | B17: فعل و زمان‌ها (هفته 1) | C17: Modalverben im Perfekt (Ersatzinfinitiv) (افعال وجهی در ماضی نقلی (مصدر جایگزین)) | D17: متوسط | E17: 7 | F17: 68 | G17: ارزیابی نشده
A18: 14 | B18: فعل و زمان‌ها (هفته 1) | C18: Subjektive Bedeutung der Modalverben (معنای ذهنی (احتمال و نقل‌قول) افعال وجهی) | D18: متوسط | E18: 7 | F18: 68 | G18: ارزیابی نشده
A19: 15 | B19: مجهول (Passiv) (هفته 2) | C19: Vorgangspassiv im Präsens (مجهول فرایندی در زمان حال) | D19: متوسط | E19: 8 | F19: 64 | G19: ارزیابی نشده
A20: 16 | B20: مجهول (Passiv) (هفته 2) | C20: Vorgangspassiv im Präteritum (مجهول فرایندی در ماضی ساده) | D20: متوسط | E20: 8 | F20: 64 | G20: ارزیابی نشده
A21: 17 | B21: مجهول (Passiv) (هفته 2) | C21: Vorgangspassiv im Perfekt und Plusquamperfekt (مجهول فرایندی در ماضی نقلی و بعید) | D21: متوسط | E21: 9 | F21: 64 | G21: ارزیابی نشده
A22: 18 | B22: مجهول (Passiv) (هفته 2) | C22: Passiv mit Modalverben (مجهول با افعال وجهی) | D22: متوسط | E22: 9 | F22: 64 | G22: ارزیابی نشده
A23: 19 | B23: مجهول (Passiv) (هفته 2) | C23: Passiv im Futur (مجهول در زمان آینده) | D23: متوسط | E23: 10 | F23: 64 | G23: ارزیابی نشده
A24: 20 | B24: مجهول (Passiv) (هفته 2) | C24: Zustandspassiv (مجهول حالتی (نتیجه)) | D24: دشوار | E24: 10 | F24: 64 | G24: ارزیابی نشده
... A53: 49 | B53: گفتار غیرمستقیم و جمله‌های وابسته (هفته 4) | C53: Redewiedergabe mit Verben und Wendungen (نقل‌قول با فعل‌ها و عبارت‌های گزارشی) | D53: دشوار | E53: 25 | F53: 65 | G53: ارزیابی نشده
A54: 50 | B54: گفتار غیرمستقیم و جمله‌های وابسته (هفته 4) | C54: Nebensatz mit dass (جمله وابسته با dass) | D54: آسان | E54: 25 | F54: — | G54: ارزیابی نشده
A55: 51 | B55: گفتار غیرمستقیم و جمله‌های وابسته (هفته 4) | C55: Indirekte Fragesätze mit ob und W-Fragewort (جمله‌های پرسشی غیرمستقیم با ob و واژه‌های پرسشی) | D55: آسان | E55: 26 | F55: — | G55: ارزیابی نشده
A56: 52 | B56: گفتار غیرمستقیم و جمله‌های وابسته (هفته 4) | C56: Stellung von Haupt- und Nebensatz (جایگاه جمله پایه و جمله وابسته) | D56: آسان | E56: 26 | F56: — | G56: ارزیابی نشده
A57: 53 | B57: گفتار غیرمستقیم و جمله‌های وابسته (هفته 4) | C57: Infinitiv mit zu (مصدر با zu) | D57: آسان | E57: 27 | F57: 67 | G57: ارزیابی نشده
A58: 54 | B58: گفتار غیرمستقیم و جمله‌های وابسته (هفته 4) | C58: Finalsätze: um ... zu und damit (جمله‌های هدفی: um ... zu و damit) | D58: متوسط | E58: 27 | F58: 67 | G58: ارزیابی نشده
A59: 55 | B59: گفتار غیرمستقیم و جمله‌های وابسته (هفته 4) | C59: (An)statt ... zu und ohne ... zu ((An)statt ... zu و ohne ... zu) | D59: متوسط | E59: 28 | F59: 67 | G59: ارزیابی نشده
A60: 56 | B60: گفتار غیرمستقیم و جمله‌های وابسته (هفته 4) | C60: Infinitiv mit zu nach Adjektiven und Nomen (مصدر با zu بعد از صفت و اسم) | D60: متوسط | E60: 28 | F60: 67 | G60: ارزیابی نشده
A61: 57 | B61: حروف ربط (Konnektoren) (هفته 5) | C61: Kausale Konnektoren: weil, da, denn (حروف ربط علّی: weil، da، denn) | D61: آسان | E61: 29 | F61: 66 | G61: ارزیابی نشده
A62: 58 | B62: حروف ربط (Konnektoren) (هفته 5) | C62: Kausale Adverbien: deshalb, darum, deswegen (قیدهای علّی: deshalb، darum، deswegen) | D62: آسان | E62: 29 | F62: 66 | G62: ارزیابی نشده
A63: 59 | B63: حروف ربط (Konnektoren) (هفته 5) | C63: Konzessive Sätze: obwohl und obgleich (جمله‌های تقابلی: obwohl و obgleich) | D63: متوسط | E63: 30 | F63: 66 | G63: ارزیابی نشده
A64: 60 | B64: حروف ربط (Konnektoren) (هفته 5) | C64: Konzessive Verbindungen: zwar ... aber, dennoch, selbst wenn (پیوندهای تقابلی: zwar ... aber، dennoch، selbst wenn) | D64: متوسط | E64: 30 | F64: 66 | G64: ارزیابی نشده
A65: 61 | B65: حروف ربط (Konnektoren) (هفته 5) | C65: Konsekutive Sätze: sodass und so ... dass (جمله‌های نتیجه‌ای: sodass و so ... dass) | D65: دشوار | E65: 31 | F65: 66 | G65: ارزیابی نشده
A66: 62 | B66: حروف ربط (Konnektoren) (هفته 5) | C66: Konsekutive Adverbien: folglich, infolgedessen, daher (قیدهای نتیجه‌ای: folglich، infolgedessen، daher) | D66: دشوار | E66: 31 | F66: 66 | G66: ارزیابی نشده
A67: 63 | B67: حروف ربط (Konnektoren) (هفته 5) | C67: Modale Nebensätze: indem und dadurch, dass (جمله‌های شیوه‌ای: indem و dadurch, dass) | D67: دشوار | E67: 32 | F67: 66 | G67: ارزیابی نشده
A68: 64 | B68: حروف ربط (Konnektoren) (هفته 5) | C68: Adversative Konnektoren: während und wohingegen (حروف ربط تقابلی: während و wohingegen) | D68: دشوار | E68: 32 | F68: 66 | G68: ارزیابی نشده
... A83: 79 | B83: جمله موصولی، صفت و اسم‌سازی (هفته 6) | C83: Erweiterte Partizipialattribute (صفت‌های وصفی گسترده) | D83: دشوار | E83: 40 | F83: 65 | G83: ارزیابی نشده
...

Sheet نیازمندی‌های آزمون
A1: ساختار آزمون ÖSD Zertifikat B2 و آنچه برای نمره بالای ۹۵٪ لازم دارید
A3: الف) ساختار آزمون
A4: ماژول | B4: مدت | C4: محتوا | D4: میزان اطمینان | E4: توضیح
A5: Lesen (خواندن) | B5: ۹۰ دقیقه | C5: چهار تکلیف با متن‌هایی متنوع از نظر نوع، محتوا و منبع؛ درک پیام کلی و جزئیات. | D5: تأییدشده از منابع رسمی ÖSD و مراکز آزمون | E5: ماژول کتبی
A6: Hören (شنیدن) | B6: حدود ۳۰ دقیقه (تخمینی) | C6: متن‌های گفتاری معیار و واقعی؛ در یکی از منابع فقط ۲ تکلیف ذکر شده است. | D6: با سایت رسمی ÖSD (osd.at) یا مرکز آزمون خود تطبیق دهید (تعداد تکلیف‌ها و مدت دقیق) | E6: ماژول کتبی
A7: Schreiben (نوشتن) | B7: ۹۰ دقیقه | C7: نوشتن متن‌هایی مانند نامه یا ایمیل رسمی، بیان و استدلال نظر و توصیف؛ دو ارزیاب ماژول‌های نوشتن و گفتار را نمره می‌دهند. | D7: با سایت رسمی ÖSD (osd.at) یا مرکز آزمون خود تطبیق دهید (نوع و تعداد تکلیف‌ها) | E7: ماژول کتبی
A8: Sprechen (گفتار) | B8: ۱۵ تا ۲۰ دقیقه | C8: ماژول شفاهی؛ شامل توصیف تصویر یا بحث؛ دو ارزیاب حضور دارند. | D8: تأییدشده از منابع رسمی ÖSD و مراکز آزمون (قالب دقیق تکلیف‌ها را با مرکز آزمون تطبیق دهید) | E8: ماژول شفاهی
A9: مجموع بخش کتبی | B9: حدود ۲۱۰ دقیقه | C9: خواندن، شنیدن و نوشتن در یک نشست؛ بخش شفاهی جداگانه است. | D9: محاسبه از منابع بالا
A10: نمره‌دهی و حد قبولی | B10: نامشخص در این فایل | C10: سقف نمره هر ماژول و حداقل نمره قبولی (که معمولاً درصدی از نمره هر ماژول است) را از راهنمای رسمی بخوانید و در برگه «آزمون‌های آزمایشی» (خانه B3 و B4) وارد کنید. | D10: با سایت رسمی ÖSD (osd.at) یا مرکز آزمون خود تطبیق دهید | E10: مهم
A12: ب) آنچه واقعاً برای نمره بالای ۹۵٪ لازم است
A13: حوزه | B13: آنچه لازم دارید | C13: معیار سنجش | D13: منبع یا ابزار پیشنهادی
A14: دانش گرامری | B14: تسلط روی ۱۴۰ مبحث این برنامه، به‌ویژه مجهول، Konjunktiv II، گفتار غیرمستقیم، حروف ربط، وجه وصفی و سبک اسمی. | C14: پاسخ درست ۹۵٪ یا بیشتر در تمرین‌های هر مبحث؛ استفاده خودبه‌خودی در گفتار و نوشتار، نه فقط تشخیص. | D14: برگه «فهرست گرامر B2»؛ کتاب تمرین Grammatik aktiv B1/B2 از Cornelsen؛ سایت‌های dwds.de برای بررسی کاربرد واژه‌ها.
A15: دامنه واژگان | B15: حدود ۴۵۰۰ تا ۵۵۰۰ واژه فعال در حوزه‌های روزمره، شغلی و اجتماعی؛ ترکیب‌های ثابت و عبارت‌های ربط. | C15: روزانه ۱۵ واژه جدید و ۵ مرور؛ خودآزمایی هفتگی ≥ ۹۰٪. | D15: کارت‌های مرور فاصله‌دار؛ خواندن مقاله‌های Deutsche Welle و tagesschau.de؛ فرهنگ لغت dwds.de.
A16: خواندن | B16: تشخیص سریع ایده اصلی، موضع نویسنده، جزئیات و ساختار متن؛ مدیریت زمان ۹۰ دقیقه. | C16: هر تکلیف حداکثر ۲۰ دقیقه؛ دقت ≥ ۹۵٪ در سه شبیه‌سازی آخر. | D16: نمونه‌آزمون‌های رسمی (Modellsätze) از osd.at یا مرکز آزمون؛ مقاله‌های روزنامه و مجله.
A17: شنیدن | B17: درک آلمانی معیار با سرعت طبیعی و تمرکز بر کلمات کلیدی، نگرش‌ها و گزینه‌های فریبنده. | C17: پاسخ درست ≥ ۹۵٪ با یک‌بار شنیدن؛ توانایی خلاصه‌کردن شنیده‌ها. | D17: پادکست‌ها و گزارش‌های Deutsche Welle؛ خبرهای tagesschau.de؛ فایل‌های صوتی نمونه‌آزمون‌های رسمی.
A18: نوشتن | B18: الگوهای ثابت نامه رسمی و غیررسمی، متن نظر، شکایت و توصیف نمودار؛ ربط منطقی، دقت دستوری و تنوع واژگان. | C18: هر متن در زمان تعیین‌شده؛ ≤ ۲ خطای دستوری در هر ۱۰۰ کلمه؛ دریافت بازخورد از معلم یا هم‌زبان. | D18: برگه «برنامه ۷۰ روزه» (فهرست عبارت‌های ربط)؛ معیارهای نمره‌دهی نوشتن در راهنمای رسمی ÖSD.
A19: گفتار | B19: تک‌گویی منسجم، توصیف تصویر، بحث و استدلال، پاسخ به پرسش‌های ناگهانی؛ روانی و تلفظ. | C19: ضبط و ارزیابی هفتگی؛ حداقل ۳ شبیه‌سازی با شریک یا معلم. | D19: شریک زبانی؛ ضبط صدا با گوشی؛ معلم برای بازخورد.
A20: مدیریت زمان و استرس | B20: تمرین کامل آزمون در شرایط واقعی، پاسخ‌نویسی بدون تاخیر و بازبینی نهایی. | C20: شش آزمون آزمایشی (روزهای ۱۴، ۲۸، ۴۲، ۵۶، ۶۳ و ۷۰) با ثبت نمره. | D20: برگه «آزمون‌های آزمایشی».
A22: واقع‌بینانه باشید | B22: نمره ۹۵٪ یعنی تقریباً بی‌خطا بودن در همه مهارت‌ها. دو مهارت نوشتن و گفتار را ارزیاب‌ها به‌صورت ذهنی نمره می‌دهند؛ بنابراین حتی با آمادگی عالی ممکن است چند درصد از دست برود. هدف عملی و مطمئن‌تر: ۸۵ تا ۹۰٪ در همه مهارت‌ها و ۹۵٪ در خواندن و شنیدن.
A23: بازخورد انسانی ضروری است | B23: برای نوشتن و گفتار حتماً از یک معلم یا هم‌زبان بازخورد بگیرید؛ خودارزیابی به‌تنهایی معمولاً خطاهای ثابت را نمی‌بیند.
A24: اطلاعات رسمی را تأیید کنید | B24: قالب دقیق تکلیف‌ها، سقف نمره و حد قبولی ممکن است تغییر کرده باشد. پیش از شروع، راهنمای رسمی و نمونه‌آزمون جدید را از osd.at یا مرکز آزمون بگیرید.
A25: منابع این برگه: بروشور ÖSD Zertifikat B2 (osd.at) و سند اطلاعات دوره WIFI اتریش. مقدارهای تخمینی با برچسب «تخمینی» یا «تطبیق دهید» مشخص شده‌اند.

Sheet آزمون‌های آزمایشی
A1: شش آزمون آزمایشی کامل و ثبت نمره
A3: سقف نمره هر مهارت (فرض اولیه؛ طبق راهنمای رسمی اصلاح کنید) | B3: 100 | C3: مقدار ۱۰۰ فرض ساده برای محاسبه درصد است؛ اگر سقف نمره در ÖSD متفاوت است، همین خانه را تغییر دهید.
A4: درصد هدف | B4: 0.95
A6: آزمون | B6: روز برنامه | C6: تاریخ | D6: Lesen (امتیاز) | E6: Hören (امتیاز) | F6: Schreiben (امتیاز) | G6: Sprechen (امتیاز) | H6: Lesen ٪ | I6: Hören ٪ | J6: Schreiben ٪ | K6: Sprechen ٪ | L6: میانگین ٪ | M6: ضعیف‌ترین مهارت | N6: وضعیت نسبت به هدف
A7: نمونه (در محاسبه نیست) | B7: — | C7: — | D7: 80 | E7: 85 | F7: 70 | G7: 75 | H7: =D7/$B$3 -> 0.8 | I7: =E7/$B$3 -> 0.85 | J7: =F7/$B$3 -> 0.7 | K7: =G7/$B$3 -> 0.75 | L7: =AVERAGE(H7:K7) -> 0.775 | M7: =INDEX($D$6:$G$6,MATCH(MIN(H7:K7),H7:K7,0)) -> Schreiben (امتیاز) | N7: نمونه
A8: آزمون آزمایشی 1 | B8: 14 | C8: ='پیگیری پیشرفت'!$B$3+B8-1 -> 46316 | H8: =IF(D8="","",D8/$B$3) | I8: =IF(E8="","",E8/$B$3) | J8: =IF(F8="","",F8/$B$3) | K8: =IF(G8="","",G8/$B$3) | L8: =IF(COUNT(H8:K8)=0,"",AVERAGE(H8:K8)) | M8: =IF(COUNT(H8:K8)=0,"",INDEX($D$6:$G$6,MATCH(MIN(H8:K8),H8:K8,0))) | N8: =IF(L8="","",IF(L8>=$B$4,"هدف محقق شد","زیر هدف"))
A9: آزمون آزمایشی 2 | B9: 28 | C9: ='پیگیری پیشرفت'!$B$3+B9-1 -> 46330 | H9: =IF(D9="","",D9/$B$3) | I9: =IF(E9="","",E9/$B$3) | J9: =IF(F9="","",F9/$B$3) | K9: =IF(G9="","",G9/$B$3) | L9: =IF(COUNT(H9:K9)=0,"",AVERAGE(H9:K9)) | M9: =IF(COUNT(H9:K9)=0,"",INDEX($D$6:$G$6,MATCH(MIN(H9:K9),H9:K9,0))) | N9: =IF(L9="","",IF(L9>=$B$4,"هدف محقق شد","زیر هدف"))
A10: آزمون آزمایشی 3 | B10: 42 | C10: ='پیگیری پیشرفت'!$B$3+B10-1 -> 46344 | H10: =IF(D10="","",D10/$B$3) | I10: =IF(E10="","",E10/$B$3) | J10: =IF(F10="","",F10/$B$3) | K10: =IF(G10="","",G10/$B$3) | L10: =IF(COUNT(H10:K10)=0,"",AVERAGE(H10:K10)) | M10: =IF(COUNT(H10:K10)=0,"",INDEX($D$6:$G$6,MATCH(MIN(H10:K10),H10:K10,0))) | N10: =IF(L10="","",IF(L10>=$B$4,"هدف محقق شد","زیر هدف"))
A11: آزمون آزمایشی 4 | B11: 56 | C11: ='پیگیری پیشرفت'!$B$3+B11-1 -> 46358 | H11: =IF(D11="","",D11/$B$3) | I11: =IF(E11="","",E11/$B$3) | J11: =IF(F11="","",F11/$B$3) | K11: =IF(G11="","",G11/$B$3) | L11: =IF(COUNT(H11:K11)=0,"",AVERAGE(H11:K11)) | M11: =IF(COUNT(H11:K11)=0,"",INDEX($D$6:$G$6,MATCH(MIN(H11:K11),H11:K11,0))) | N11: =IF(L11="","",IF(L11>=$B$4,"هدف محقق شد","زیر هدف"))
A12: آزمون آزمایشی 5 | B12: 63 | C12: ='پیگیری پیشرفت'!$B$3+B12-1 -> 46365 | H12: =IF(D12="","",D12/$B$3) | I12: =IF(E12="","",E12/$B$3) | J12: =IF(F12="","",F12/$B$3) | K12: =IF(G12="","",G12/$B$3) | L12: =IF(COUNT(H12:K12)=0,"",AVERAGE(H12:K12)) | M12: =IF(COUNT(H12:K12)=0,"",INDEX($D$6:$G$6,MATCH(MIN(H12:K12),H12:K12,0))) | N12: =IF(L12="","",IF(L12>=$B$4,"هدف محقق شد","زیر هدف"))
A13: آزمون آزمایشی 6 | B13: 70 | C13: ='پیگیری پیشرفت'!$B$3+B13-1 -> 46372 | H13: =IF(D13="","",D13/$B$3) | I13: =IF(E13="","",E13/$B$3) | J13: =IF(F13="","",F13/$B$3) | K13: =IF(G13="","",G13/$B$3) | L13: =IF(COUNT(H13:K13)=0,"",AVERAGE(H13:K13)) | M13: =IF(COUNT(H13:K13)=0,"",INDEX($D$6:$G$6,MATCH(MIN(H13:K13),H13:K13,0))) | N13: =IF(L13="","",IF(L13>=$B$4,"هدف محقق شد","زیر هدف"))
A14: میانگین همه آزمون‌ها | H14: =IFERROR(AVERAGE(H8:H13),"") | I14: =IFERROR(AVERAGE(I8:I13),"") | J14: =IFERROR(AVERAGE(J8:J13),"") | K14: =IFERROR(AVERAGE(K8:K13),"") | L14: =IFERROR(AVERAGE(L8:L13),"")
A17: راهنمای اجرای هر آزمون آزمایشی
A18: مهارت | B18: زمان واقعی | C18: قواعد شبیه‌سازی
A19: Lesen | B19: ۹۰ دقیقه | C19: بدون فرهنگ لغت و تلفن؛ زمان‌سنج روشن؛ بعد از پایان فقط تصحیح کنید و علت هر خطا را بنویسید.
A20: Hören | B20: حدود ۳۰ دقیقه | C20: هر فایل صوتی طبق شرایط آزمون؛ پس از پایان، دوباره گوش دهید و متن را تطبیق دهید.
A21: Schreiben | B21: ۹۰ دقیقه | C21: دست‌نویس یا تایپ بدون ابزار اصلاح خودکار؛ سپس با معیارهای محتوا، ساختار، واژگان و صحت دستوری ارزیابی کنید و یک نفر دیگر بخواند.
A22: Sprechen | B22: ۱۵ تا ۲۰ دقیقه | C22: با معلم یا شریک زبانی؛ ضبط صدا؛ پس از پایان، روانی، دقت دستوری و پیوستگی را بررسی کنید.
A24: نکته: خانه‌های زرد رنگ ورودی هستند. نمره هر مهارت را پس از تصحیح وارد کنید.

Sheet پیگیری پیشرفت
A1: پیگیری پیشرفت برنامه ۷۰ روزه
A3: تاریخ شروع برنامه (قابل تغییر) | B3: 46303
A4: تعداد کل روزها | B4: =COUNT('برنامه ۷۰ روزه'!$A$5:$A$74) -> 70
A5: روزهای انجام‌شده | B5: =COUNTIF('برنامه ۷۰ روزه'!$Y$5:$Y$74,"انجام شد") -> 0
A6: روزهای نیمه‌کاره | B6: =COUNTIF('برنامه ۷۰ روزه'!$Y$5:$Y$74,"نیمه‌کاره") -> 0
A7: درصد پیشرفت واقعی | B7: =(B5+0.5*B6)/B4 -> 0
A8: پیشرفت مورد انتظار تا امروز | B8: =B9/B4 -> 0
A9: روزهای سپری‌شده طبق تقویم | B9: =MAX(0,MIN(B4,TODAY()-B3+1)) -> 0
A10: اختلاف با برنامه (مثبت = جلوتر) | B10: =B7-B8 -> 0
A11: ساعات مطالعه انجام‌شده (تقریبی) | B11: =(SUMIFS('برنامه ۷۰ روزه'!$W$5:$W$74,'برنامه ۷۰ روزه'!$Y$5:$Y$74,"انجام شد")+0.5*SUMIFS('برنامه ۷۰ روزه'!$W$5:$W$74,'برنامه ۷۰ روزه'!$Y$5:$Y$74,"نیمه‌کاره"))/60 -> 0
A12: تعداد آزمون‌های آزمایشی ثبت‌شده | B12: =COUNT('آزمون‌های آزمایشی'!$L$8:$L$13) -> 0
A13: میانگین کل آزمون‌های آزمایشی | B13: =IFERROR(AVERAGE('آزمون‌های آزمایشی'!$L$8:$L$13),"هنوز ثبت نشده") -> هنوز ثبت نشده
A14: میانگین آخرین آزمون ثبت‌شده | B14: =IFERROR(LOOKUP(2,1/('آزمون‌های آزمایشی'!$L$8:$L$13<>""),'آزمون‌های آزمایشی'!$L$8:$L$13),"هنوز ثبت نشده") -> هنوز ثبت نشده
A15: میانگین هر مهارت در آزمون‌های آزمایشی
B16: Lesen | C16: Hören | D16: Schreiben | E16: Sprechen
B17: =IFERROR(AVERAGE('آزمون‌های آزمایشی'!$H$8:$H$13),"") | C17: =IFERROR(AVERAGE('آزمون‌های آزمایشی'!$I$8:$I$13),"") | D17: =IFERROR(AVERAGE('آزمون‌های آزمایشی'!$J$8:$J$13),"") | E17: =IFERROR(AVERAGE('آزمون‌های آزمایشی'!$K$8:$K$13),"")
A19: پیشرفت هفتگی
A20: هفته | B20: روزهای برنامه | C20: انجام‌شده | D20: نیمه‌کاره | E20: درصد پیشرفت هفته | F20: دقایق برنامه‌ریزی‌شده | G20: دقایق انجام‌شده
A21: 1 | B21: =COUNTIF('برنامه ۷۰ روزه'!$B$5:$B$74,A21) -> 7 | C21: =COUNTIFS('برنامه ۷۰ روزه'!$B$5:$B$74,A21,'برنامه ۷۰ روزه'!$Y$5:$Y$74,"انجام شد") -> 0 | D21: =COUNTIFS('برنامه ۷۰ روزه'!$B$5:$B$74,A21,'برنامه ۷۰ روزه'!$Y$5:$Y$74,"نیمه‌کاره") -> 0 | E21: =IF(B21=0,0,(C21+0.5*D21)/B21) -> 0 | F21: =SUMIFS('برنامه ۷۰ روزه'!$W$5:$W$74,'برنامه ۷۰ روزه'!$B$5:$B$74,A21) -> 1130 | G21: =SUMIFS('برنامه ۷۰ روزه'!$W$5:$W$74,'برنامه ۷۰ روزه'!$B$5:$B$74,A21,'برنامه ۷۰ روزه'!$Y$5:$Y$74,"انجام شد")+0.5*SUMIFS('برنامه ۷۰ روزه'!$W$5:$W$74,'برنامه ۷۰ روزه'!$B$5:$B$74,A21,'برنامه ۷۰ روزه'!$Y$5:$Y$74,"نیمه‌کاره") -> 0
A22: 2 | B22: =COUNTIF('برنامه ۷۰ روزه'!$B$5:$B$74,A22) -> 7 | C22: =COUNTIFS('برنامه ۷۰ روزه'!$B$5:$B$74,A22,'برنامه ۷۰ روزه'!$Y$5:$Y$74,"انجام شد") -> 0 | D22: =COUNTIFS('برنامه ۷۰ روزه'!$B$5:$B$74,A22,'برنامه ۷۰ روزه'!$Y$5:$Y$74,"نیمه‌کاره") -> 0 | E22: =IF(B22=0,0,(C22+0.5*D22)/B22) -> 0 | F22: =SUMIFS('برنامه ۷۰ روزه'!$W$5:$W$74,'برنامه ۷۰ روزه'!$B$5:$B$74,A22) -> 1220 | G22: =SUMIFS('برنامه ۷۰ روزه'!$W$5:$W$74,'برنامه ۷۰ روزه'!$B$5:$B$74,A22,'برنامه ۷۰ روزه'!$Y$5:$Y$74,"انجام شد")+0.5*SUMIFS('برنامه ۷۰ روزه'!$W$5:$W$74,'برنامه ۷۰ روزه'!$B$5:$B$74,A22,'برنامه ۷۰ روزه'!$Y$5:$Y$74,"نیمه‌کاره") -> 0
A23: 3 | B23: =COUNTIF('برنامه ۷۰ روزه'!$B$5:$B$74,A23) -> 7 | C23: =COUNTIFS('برنامه ۷۰ روزه'!$B$5:$B$74,A23,'برنامه ۷۰ روزه'!$Y$5:$Y$74,"انجام شد") -> 0 | D23: =COUNTIFS('برنامه ۷۰ روزه'!$B$5:$B$74,A23,'برنامه ۷۰ روزه'!$Y$5:$Y$74,"نیمه‌کاره") -> 0 | E23: =IF(B23=0,0,(C23+0.5*D23)/B23) -> 0 | F23: =SUMIFS('برنامه ۷۰ روزه'!$W$5:$W$74,'برنامه ۷۰ روزه'!$B$5:$B$74,A23) -> 1130 | G23: =SUMIFS('برنامه ۷۰ روزه'!$W$5:$W$74,'برنامه ۷۰ روزه'!$B$5:$B$74,A23,'برنامه ۷۰ روزه'!$Y$5:$Y$74,"انجام شد")+0.5*SUMIFS('برنامه ۷۰ روزه'!$W$5:$W$74,'برنامه ۷۰ روزه'!$B$5:$B$74,A23,'برنامه ۷۰ روزه'!$Y$5:$Y$74,"نیمه‌کاره") -> 0
A24: 4 | B24: =COUNTIF('برنامه ۷۰ روزه'!$B$5:$B$74,A24) -> 7 | C24: =COUNTIFS('برنامه ۷۰ روزه'!$B$5:$B$74,A24,'برنامه ۷۰ روزه'!$Y$5:$Y$74,"انجام شد") -> 0 | D24: =COUNTIFS('برنامه ۷۰ روزه'!$B$5:$B$74,A24,'برنامه ۷۰ روزه'!$Y$5:$Y$74,"نیمه‌کاره") -> 0 | E24: =IF(B24=0,0,(C24+0.5*D24)/B24) -> 0 | F24: =SUMIFS('برنامه ۷۰ روزه'!$W$5:$W$74,'برنامه ۷۰ روزه'!$B$5:$B$74,A24) -> 1220 | G24: =SUMIFS('برنامه ۷۰ روزه'!$W$5:$W$74,'برنامه ۷۰ روزه'!$B$5:$B$74,A24,'برنامه ۷۰ روزه'!$Y$5:$Y$74,"انجام شد")+0.5*SUMIFS('برنامه ۷۰ روزه'!$W$5:$W$74,'برنامه ۷۰ روزه'!$B$5:$B$74,A24,'برنامه ۷۰ روزه'!$Y$5:$Y$74,"نیمه‌کاره") -> 0
A25: 5 | B25: =COUNTIF('برنامه ۷۰ روزه'!$B$5:$B$74,A25) -> 7 | C25: =COUNTIFS('برنامه ۷۰ روزه'!$B$5:$B$74,A25,'برنامه ۷۰ روزه'!$Y$5:$Y$74,"انجام شد") -> 0 | D25: =COUNTIFS('برنامه ۷۰ روزه'!$B$5:$B$74,A25,'برنامه ۷۰ روزه'!$Y$5:$Y$74,"نیمه‌کاره") -> 0 | E25: =IF(B25=0,0,(C25+0.5*D25)/B25) -> 0 | F25: =SUMIFS('برنامه ۷۰ روزه'!$W$5:$W$74,'برنامه ۷۰ روزه'!$B$5:$B$74,A25) -> 1130 | G25: =SUMIFS('برنامه ۷۰ روزه'!$W$5:$W$74,'برنامه ۷۰ روزه'!$B$5:$B$74,A25,'برنامه ۷۰ روزه'!$Y$5:$Y$74,"انجام شد")+0.5*SUMIFS('برنامه ۷۰ روزه'!$W$5:$W$74,'برنامه ۷۰ روزه'!$B$5:$B$74,A25,'برنامه ۷۰ روزه'!$Y$5:$Y$74,"نیمه‌کاره") -> 0
A26: 6 | B26: =COUNTIF('برنامه ۷۰ روزه'!$B$5:$B$74,A26) -> 7 | C26: =COUNTIFS('برنامه ۷۰ روزه'!$B$5:$B$74,A26,'برنامه ۷۰ روزه'!$Y$5:$Y$74,"انجام شد") -> 0 | D26: =COUNTIFS('برنامه ۷۰ روزه'!$B$5:$B$74,A26,'برنامه ۷۰ روزه'!$Y$5:$Y$74,"نیمه‌کاره") -> 0 | E26: =IF(B26=0,0,(C26+0.5*D26)/B26) -> 0 | F26: =SUMIFS('برنامه ۷۰ روزه'!$W$5:$W$74,'برنامه ۷۰ روزه'!$B$5:$B$74,A26) -> 1220 | G26: =SUMIFS('برنامه ۷۰ روزه'!$W$5:$W$74,'برنامه ۷۰ روزه'!$B$5:$B$74,A26,'برنامه ۷۰ روزه'!$Y$5:$Y$74,"انجام شد")+0.5*SUMIFS('برنامه ۷۰ روزه'!$W$5:$W$74,'برنامه ۷۰ روزه'!$B$5:$B$74,A26,'برنامه ۷۰ روزه'!$Y$5:$Y$74,"نیمه‌کاره") -> 0
A27: 7 | B27: =COUNTIF('برنامه ۷۰ روزه'!$B$5:$B$74,A27) -> 7 | C27: =COUNTIFS('برنامه ۷۰ روزه'!$B$5:$B$74,A27,'برنامه ۷۰ روزه'!$Y$5:$Y$74,"انجام شد") -> 0 | D27: =COUNTIFS('برنامه ۷۰ روزه'!$B$5:$B$74,A27,'برنامه ۷۰ روزه'!$Y$5:$Y$74,"نیمه‌کاره") -> 0 | E27: =IF(B27=0,0,(C27+0.5*D27)/B27) -> 0 | F27: =SUMIFS('برنامه ۷۰ روزه'!$W$5:$W$74,'برنامه ۷۰ روزه'!$B$5:$B$74,A27) -> 1130 | G27: =SUMIFS('برنامه ۷۰ روزه'!$W$5:$W$74,'برنامه ۷۰ روزه'!$B$5:$B$74,A27,'برنامه ۷۰ روزه'!$Y$5:$Y$74,"انجام شد")+0.5*SUMIFS('برنامه ۷۰ روزه'!$W$5:$W$74,'برنامه ۷۰ روزه'!$B$5:$B$74,A27,'برنامه ۷۰ روزه'!$Y$5:$Y$74,"نیمه‌کاره") -> 0
A28: 8 | B28: =COUNTIF('برنامه ۷۰ روزه'!$B$5:$B$74,A28) -> 7 | C28: =COUNTIFS('برنامه ۷۰ روزه'!$B$5:$B$74,A28,'برنامه ۷۰ روزه'!$Y$5:$Y$74,"انجام شد") -> 0 | D28: =COUNTIFS('برنامه ۷۰ روزه'!$B$5:$B$74,A28,'برنامه ۷۰ روزه'!$Y$5:$Y$74,"نیمه‌کاره") -> 0 | E28: =IF(B28=0,0,(C28+0.5*D28)/B28) -> 0 | F28: =SUMIFS('برنامه ۷۰ روزه'!$W$5:$W$74,'برنامه ۷۰ روزه'!$B$5:$B$74,A28) -> 1220 | G28: =SUMIFS('برنامه ۷۰ روزه'!$W$5:$W$74,'برنامه ۷۰ روزه'!$B$5:$B$74,A28,'برنامه ۷۰ روزه'!$Y$5:$Y$74,"انجام شد")+0.5*SUMIFS('برنامه ۷۰ روزه'!$W$5:$W$74,'برنامه ۷۰ روزه'!$B$5:$B$74,A28,'برنامه ۷۰ روزه'!$Y$5:$Y$74,"نیمه‌کاره") -> 0
A29: 9 | B29: =COUNTIF('برنامه ۷۰ روزه'!$B$5:$B$74,A29) -> 7 | C29: =COUNTIFS('برنامه ۷۰ روزه'!$B$5:$B$74,A29,'برنامه ۷۰ روزه'!$Y$5:$Y$74,"انجام شد") -> 0 | D29: =COUNTIFS('برنامه ۷۰ روزه'!$B$5:$B$74,A29,'برنامه ۷۰ روزه'!$Y$5:$Y$74,"نیمه‌کاره") -> 0 | E29: =IF(B29=0,0,(C29+0.5*D29)/B29) -> 0 | F29: =SUMIFS('برنامه ۷۰ روزه'!$W$5:$W$74,'برنامه ۷۰ روزه'!$B$5:$B$74,A29) -> 1220 | G29: =SUMIFS('برنامه ۷۰ روزه'!$W$5:$W$74,'برنامه ۷۰ روزه'!$B$5:$B$74,A29,'برنامه ۷۰ روزه'!$Y$5:$Y$74,"انجام شد")+0.5*SUMIFS('برنامه ۷۰ روزه'!$W$5:$W$74,'برنامه ۷۰ روزه'!$B$5:$B$74,A29,'برنامه ۷۰ روزه'!$Y$5:$Y$74,"نیمه‌کاره") -> 0
A30: 10 | B30: =COUNTIF('برنامه ۷۰ روزه'!$B$5:$B$74,A30) -> 7 | C30: =COUNTIFS('برنامه ۷۰ روزه'!$B$5:$B$74,A30,'برنامه ۷۰ روزه'!$Y$5:$Y$74,"انجام شد") -> 0 | D30: =COUNTIFS('برنامه ۷۰ روزه'!$B$5:$B$74,A30,'برنامه ۷۰ روزه'!$Y$5:$Y$74,"نیمه‌کاره") -> 0 | E30: =IF(B30=0,0,(C30+0.5*D30)/B30) -> 0 | F30: =SUMIFS('برنامه ۷۰ روزه'!$W$5:$W$74,'برنامه ۷۰ روزه'!$B$5:$B$74,A30) -> 1220 | G30: =SUMIFS('برنامه ۷۰ روزه'!$W$5:$W$74,'برنامه ۷۰ روزه'!$B$5:$B$74,A30,'برنامه ۷۰ روزه'!$Y$5:$Y$74,"انجام شد")+0.5*SUMIFS('برنامه ۷۰ روزه'!$W$5:$W$74,'برنامه ۷۰ روزه'!$B$5:$B$74,A30,'برنامه ۷۰ روزه'!$Y$5:$Y$74,"نیمه‌کاره") -> 0
A31: جمع | B31: =SUM(B21:B30) -> 70 | C31: =SUM(C21:C30) -> 0 | D31: =SUM(D21:D30) -> 0 | F31: =SUM(F21:F30) -> 11840 | G31: =SUM(G21:G30) -> 0
A52: نمودار دوم پس از ثبت نمره‌ها در برگه «آزمون‌های آزمایشی» به‌روز می‌شود؛ تا آن زمان صفر نشان می‌دهد.

Sheet همه لینک‌ها
A1: همه لینک‌های برنامه (هر لینک در یک خانه جدا؛ اگر در برگه برنامه کلیک نشد، از اینجا باز کنید)
A3: روز | B3: مهارت | C3: تکلیف (خلاصه) | D3: آدرس لینک (قابل کپی) | E3: باز کردن
A4: 1 | B4: خواندن (Lesen) | C4: صفحه رسمی نمونه‌آزمون گوته B2 ـ Teil 1 «Moderne Lebensformen» (چهار پست انجمن؛ ۱۸ دقیقه): ۹ جمله را به افراد نسبت دهید. پاسخ را همان‌جا بررس | D4: https://bfu.goethe.de/b2_mod_2MX6/lesen.php | E4: =HYPERLINK(D4,"باز کردن") -> باز کردن
A5: 1 | B5: شنیدن (Hören) | C5: صفحه رسمی گوته B2 ـ Teil 1: پنج گفت‌وگو و جمله کوتاه (ادبیات، پرداخت نقدی، کارآموزی، پلاک دوچرخه، موضوع سمینار)؛ هر متن فقط یک بار؛ ۱۰ تکلیف | D5: https://bfu.goethe.de/b2_mod_2MX6/hoeren.php | E5: =HYPERLINK(D5,"باز کردن") -> باز کردن
A6: 1 | B6: نوشتن (Schreiben) | C6: ویدیو: «Wie schreibe ich einen Leserbrief? ـ Aufbau, Gliederung & Inhalt» (Die Merkhilfe): ساختار را یادداشت کنید، سپس متن نظرتان را بنویسید | D6: https://www.youtube.com/watch?v=jrZ1A_BLZZA | E6: =HYPERLINK(D6,"باز کردن") -> باز کردن
A7: 1 | B7: گفتار (Sprechen) | C7: ویدیوی رسمی ÖSD: «ÖSD Zertifikat B2 – Mündliche Prüfung (Sprechen)»: ساختار واقعی را ببینید، بعد یک تکلیف مشابه را ضبط کنید. سپس خودتان دربا | D7: https://www.youtube.com/watch?v=nFQljN4Oeio | E7: =HYPERLINK(D7,"باز کردن") -> باز کردن
A8: 1 | B8: واژگان (Wortschatz) | C8: متن مقاله ویکی‌پدیای آلمانی «Hochschule»: ۱۵ واژه یا ترکیب دشوار را از آن بیرون بکشید، ‌معنی و حرف تعریف را بنویسید و هر کدام را در یک جمله | D8: https://de.wikipedia.org/wiki/Hochschule | E8: =HYPERLINK(D8,"باز کردن") -> باز کردن
A9: 2 | B9: خواندن (Lesen) | C9: متن مقاله ویکی‌پدیای آلمانی «Wohnungsmarkt» (متن عمومی هم‌موضوع، نه نمونه آزمون): ۲۰ دقیقه بخوانید، ۵ جمله خلاصه بنویسید و ۸ واژه یا ترکیب د | D9: https://de.wikipedia.org/wiki/Wohnungsmarkt | E9: =HYPERLINK(D9,"باز کردن") -> باز کردن
A10: 2 | B10: شنیدن (Hören) | C10: همان صفحه ـ Teil 2: مصاحبه رادیویی با یک دانشمند درباره تغذیه و کشاورزی (مصرف گوشت، حشرات، کشاورزی شهری)؛ دو بار؛ پرسش ۱۱ تا ۱۶. | D10: https://bfu.goethe.de/b2_mod_2MX6/hoeren.php | E10: =HYPERLINK(D10,"باز کردن") -> باز کردن
A11: 2 | B11: نوشتن (Schreiben) | C11: ویدیو: «Redemittel: Die eigene Meinung ausdrücken» (DeutschLera): ۱۰ عبارت را بنویسید و در متن خودتان استفاده کنید. سپس درباره «Gesundheit u | D11: https://www.youtube.com/watch?v=Tj9P_HXTBtM | E11: =HYPERLINK(D11,"باز کردن") -> باز کردن
A12: 2 | B12: گفتار (Sprechen) | C12: ویدیو: «Prüfungsvorbereitung B2, Thema präsentieren, Meinung äußern, Redemittel» (Deutsch global). سپس خودتان درباره «Reisen und Verkehr» صح | D12: https://www.youtube.com/watch?v=ILelVsByEPk | E12: =HYPERLINK(D12,"باز کردن") -> باز کردن
A13: 2 | B13: واژگان (Wortschatz) | C13: متن مقاله ویکی‌پدیای آلمانی «Mietspiegel»: ۱۵ واژه یا ترکیب دشوار را از آن بیرون بکشید، ‌معنی و حرف تعریف را بنویسید و هر کدام را در یک جمله | D13: https://de.wikipedia.org/wiki/Mietspiegel | E13: =HYPERLINK(D13,"باز کردن") -> باز کردن
A14: 3 | B14: خواندن (Lesen) | C14: همان صفحه ـ Teil 2 «Reisefieber» (مقاله مجله؛ جای‌خالی با جمله؛ ۱۲ دقیقه): جمله‌های مناسب را در جای‌خالی‌ها بگذارید. | D14: https://bfu.goethe.de/b2_mod_2MX6/lesen.php | E14: =HYPERLINK(D14,"باز کردن") -> باز کردن
A15: 3 | B15: شنیدن (Hören) | C15: همان صفحه ـ Teil 3: گفت‌وگوی رادیویی درباره شیوه‌های زندگی جایگزین (WG، خانه سالمندان)؛ یک بار؛ تطبیق گوینده و جمله. | D15: https://bfu.goethe.de/b2_mod_2MX6/hoeren.php | E15: =HYPERLINK(D15,"باز کردن") -> باز کردن
... A353: 70 | B353: واژگان (Wortschatz) | C353: مرور خطاهای آزمون: ۱۰ واژه یا عبارتی را که در آزمون ندانستید مرور کنید. | D353: https://www.dwds.de/ | E353: =HYPERLINK(D353,"باز کردن") -> باز کردن
